Workbook
Name JK_8: #REF!
Name JKRow14: #REF!
Name JKRow13: #REF!
Name City_3: #REF!
Name JK_EMPTY: #REF!
Name JKRow8: #REF!
Name City_4: #REF!
Name JKRow9: #REF!
Name JK_2: #REF!
Name JK_7: #REF!
Name JKRow5: #REF!
Name JK_4: #REF!
Name City_5: #REF!
Name JKRow12: #REF!
Name JKRow10: #REF!
Name JK_3: #REF!
Name JKRow7: #REF!
Name JKRow6: #REF!
Name JK_6: #REF!
Name JK_5: #REF!
Name JK_10: #REF!
Name City_2: #REF!
Name JK_9: #REF!
Name RegionList: #REF!
Name City_1: #REF!
Name JKRow11: #REF!
Name JK_11: #REF!
Name JK_1: #REF!

Sheet Стоп-лист
A2: Организации и продукции, запрещенные к размещению по ФЗ «О рекламе» от 13.03.2006 г. № 38-ФЗ
A3: 1 | B3: Организации и продукции, запрещенные к размещению по ФЗ «О рекламе» от 13.03.2006 г. № 38-ФЗ
A4: 2 | B4: Ритуальные услуги
A5: 3 | B5: Религиозные организации
A6: 6 | B6: Юридические услуги по получению отсрочек от воинской службы
A7: 7 | B7: Коллекторские организации
A8: 8 | B8: Интим-услуги
A9: 9 | B9: Народные целители
A10: 10 | B10: Финансовые пирамиды/криптовалюты
A11: Сфера развлечения
A12: 11 | B12: ночные клубы
A13: 12 | B13: букмекеры
A14: 13 | B14: лотереи
A15: 14 | B15: стриптиз-клубы
A16: Сфера товары
A17: 16 | B17: эротические товары
A18: 17 | B18: электронные сигареты,кальян
A19: 18 | B19: алкогольная продукция, лекарственные средства, биологически активные добавки
A20: 19 | B20: табак, табачная продукция, табачные изделий, никотинсодержащая продукция

Sheet Стоп-лист застройщики
A2: Регион | B2: Город | C2: ЖК | D2: Разрешено застройщикам
A3: =IFERROR(__xludf.DUMMYFUNCTION("SORT(UNIQUE(CHOOSECOLS(FILTER('Основной эфир'!B3:I1149,LEN('Основной эфир'!I3:I1149)>0),1,2,5)))"),"Московская область") -> Московская область | B3: =IFERROR(__xludf.DUMMYFUNCTION("""COMPUTED_VALUE"""),"Внуково") -> Внуково | C3: =IFERROR(__xludf.DUMMYFUNCTION("""COMPUTED_VALUE"""),"А") -> А | D3: нет
A4: =IFERROR(__xludf.DUMMYFUNCTION("""COMPUTED_VALUE"""),"Московская область") -> Московская область | B4: =IFERROR(__xludf.DUMMYFUNCTION("""COMPUTED_VALUE"""),"Красногорск") -> Красногорск | C4: =IFERROR(__xludf.DUMMYFUNCTION("""COMPUTED_VALUE"""),"Б") -> Б | D4: нет
A5: =IFERROR(__xludf.DUMMYFUNCTION("""COMPUTED_VALUE"""),"Московская область") -> Московская область | B5: =IFERROR(__xludf.DUMMYFUNCTION("""COMPUTED_VALUE"""),"Мисайлово") -> Мисайлово | C5: =IFERROR(__xludf.DUMMYFUNCTION("""COMPUTED_VALUE"""),"Б") -> Б | D5: нет
A6: =IFERROR(__xludf.DUMMYFUNCTION("""COMPUTED_VALUE"""),"Московская область") -> Московская область | B6: =IFERROR(__xludf.DUMMYFUNCTION("""COMPUTED_VALUE"""),"Одинцово") -> Одинцово | C6: =IFERROR(__xludf.DUMMYFUNCTION("""COMPUTED_VALUE"""),"А") -> А | D6: нет
A7: =IFERROR(__xludf.DUMMYFUNCTION("""COMPUTED_VALUE"""),"Московская область") -> Московская область | B7: =IFERROR(__xludf.DUMMYFUNCTION("""COMPUTED_VALUE"""),"Одинцово") -> Одинцово | C7: =IFERROR(__xludf.DUMMYFUNCTION("""COMPUTED_VALUE"""),"Б") -> Б | D7: да
A8: =IFERROR(__xludf.DUMMYFUNCTION("""COMPUTED_VALUE"""),"Московская область") -> Московская область | B8: =IFERROR(__xludf.DUMMYFUNCTION("""COMPUTED_VALUE"""),"Путилково") -> Путилково | C8: =IFERROR(__xludf.DUMMYFUNCTION("""COMPUTED_VALUE"""),"А") -> А | D8: да
A9: =IFERROR(__xludf.DUMMYFUNCTION("""COMPUTED_VALUE"""),"Московская область") -> Московская область | B9: =IFERROR(__xludf.DUMMYFUNCTION("""COMPUTED_VALUE"""),"Щербинка") -> Щербинка | C9: =IFERROR(__xludf.DUMMYFUNCTION("""COMPUTED_VALUE"""),"Б") -> Б | D9: да
A10: =IFERROR(__xludf.DUMMYFUNCTION("""COMPUTED_VALUE"""),"Нижегородская область") -> Нижегородская область | B10: =IFERROR(__xludf.DUMMYFUNCTION("""COMPUTED_VALUE"""),"Нижний Новгород") -> Нижний Новгород | C10: =IFERROR(__xludf.DUMMYFUNCTION("""COMPUTED_VALUE"""),"Б") -> Б | D10: нет
A11: =IFERROR(__xludf.DUMMYFUNCTION("""COMPUTED_VALUE"""),"Оренбургская область") -> Оренбургская область | B11: =IFERROR(__xludf.DUMMYFUNCTION("""COMPUTED_VALUE"""),"Оренбург") -> Оренбург | C11: =IFERROR(__xludf.DUMMYFUNCTION("""COMPUTED_VALUE"""),"А") -> А | D11: нет
A12: =IFERROR(__xludf.DUMMYFUNCTION("""COMPUTED_VALUE"""),"Оренбургская область") -> Оренбургская область | B12: =IFERROR(__xludf.DUMMYFUNCTION("""COMPUTED_VALUE"""),"Оренбург") -> Оренбург | C12: =IFERROR(__xludf.DUMMYFUNCTION("""COMPUTED_VALUE"""),"Б") -> Б | D12: нет
A13: =IFERROR(__xludf.DUMMYFUNCTION("""COMPUTED_VALUE"""),"Республика Башкортостан") -> Республика Башкортостан | B13: =IFERROR(__xludf.DUMMYFUNCTION("""COMPUTED_VALUE"""),"Нефтекамск") -> Нефтекамск | C13: =IFERROR(__xludf.DUMMYFUNCTION("""COMPUTED_VALUE"""),"Б") -> Б | D13: нет
A14: =IFERROR(__xludf.DUMMYFUNCTION("""COMPUTED_VALUE"""),"Республика Башкортостан") -> Республика Башкортостан | B14: =IFERROR(__xludf.DUMMYFUNCTION("""COMPUTED_VALUE"""),"Октябрьский") -> Октябрьский | C14: =IFERROR(__xludf.DUMMYFUNCTION("""COMPUTED_VALUE"""),"Б") -> Б | D14: нет
A15: =IFERROR(__xludf.DUMMYFUNCTION("""COMPUTED_VALUE"""),"Республика Башкортостан") -> Республика Башкортостан | B15: =IFERROR(__xludf.DUMMYFUNCTION("""COMPUTED_VALUE"""),"Стерлитамак") -> Стерлитамак | C15: =IFERROR(__xludf.DUMMYFUNCTION("""COMPUTED_VALUE"""),"А") -> А | D15: нет
A16: =IFERROR(__xludf.DUMMYFUNCTION("""COMPUTED_VALUE"""),"Республика Башкортостан") -> Республика Башкортостан | B16: =IFERROR(__xludf.DUMMYFUNCTION("""COMPUTED_VALUE"""),"Уфа") -> Уфа | C16: =IFERROR(__xludf.DUMMYFUNCTION("""COMPUTED_VALUE"""),"А") -> А | D16: нет
A17: =IFERROR(__xludf.DUMMYFUNCTION("""COMPUTED_VALUE"""),"Республика Башкортостан") -> Республика Башкортостан | B17: =IFERROR(__xludf.DUMMYFUNCTION("""COMPUTED_VALUE"""),"Уфа") -> Уфа | C17: =IFERROR(__xludf.DUMMYFUNCTION("""COMPUTED_VALUE"""),"Б") -> Б | D17: нет
A18: =IFERROR(__xludf.DUMMYFUNCTION("""COMPUTED_VALUE"""),"Республика Татарстан") -> Республика Татарстан | B18: =IFERROR(__xludf.DUMMYFUNCTION("""COMPUTED_VALUE"""),"Казань") -> Казань | C18: =IFERROR(__xludf.DUMMYFUNCTION("""COMPUTED_VALUE"""),"А") -> А | D18: нет
A19: =IFERROR(__xludf.DUMMYFUNCTION("""COMPUTED_VALUE"""),"Республика Татарстан") -> Республика Татарстан | B19: =IFERROR(__xludf.DUMMYFUNCTION("""COMPUTED_VALUE"""),"Казань") -> Казань | C19: =IFERROR(__xludf.DUMMYFUNCTION("""COMPUTED_VALUE"""),"Б") -> Б | D19: да
A20: =IFERROR(__xludf.DUMMYFUNCTION("""COMPUTED_VALUE"""),"Республика Татарстан") -> Республика Татарстан | B20: =IFERROR(__xludf.DUMMYFUNCTION("""COMPUTED_VALUE"""),"Усады") -> Усады | C20: =IFERROR(__xludf.DUMMYFUNCTION("""COMPUTED_VALUE"""),"Б") -> Б | D20: нет
D21: нет
D22: да
D23: да
D24: да
D25: да
D26: да
D27: да
D28: да
D29: да
D30: да
D31: да
D32: нет
... D357: да

Sheet СВОД АП
C1: СВОД Умных экранов по городам
A2: Регион | B2: Город | C2: Количество пакетов | D2: Карта ЖК | E2: Количество ЖК | F2: Количество домов | G2: Количество жильцов | H2: Всего экранов | I2: Цена за размещение на 1 экране/месяц руб. без НДС для Федерального и крупного бизнеса | J2: Цена за размещение на 1 экране/месяц руб. в т.ч НДС 22% для Федерального и крупного бизнеса | K2: Стоимость размещения в 1 доме/1 месяц, руб. без НДС для Федерального и крупного бизнеса | L2: Стоимость размещения в 1 доме/1 месяц, руб. в т.ч.НДС 22% для Федерального и крупного бизнеса | M2: ФО/скрин с камеры
A3: Республика Башкортостан | B3: Уфа | C3: =IFERROR(__xludf.DUMMYFUNCTION("COUNTUNIQUEIFS('Основной эфир'!E$3:E1004, 'Основной эфир'!C$3:C1004, B3, 'Основной эфир'!E$3:E1004, ""<>"") "),10.0) -> 10 | E3: =IFERROR(__xludf.DUMMYFUNCTION("COUNTUNIQUEIFS('Основной эфир'!I$3:I1004, 'Основной эфир'!C$3:C1004, B3, 'Основной эфир'!I$3:I1004, ""<>"") "),122.0) -> 122 | F3: =IFERROR(__xludf.DUMMYFUNCTION("COUNTUNIQUEIFS('Основной эфир'!J$3:J1004, 'Основной эфир'!C$3:C1004, B3, 'Основной эфир'!J$3:J1004, ""<>"") "),176.0) -> 176 | G3: =SUMIFS('Основной эфир'!$P$3:$P$1149,'Основной эфир'!$C$3:$C$1149,B3) -> 142724.4 | H3: =SUMIFS('Основной эфир'!$Q$3:$Q$1149,'Основной эфир'!$C$3:$C$1149,B3) -> 634 | I3: {=IFERROR(INDEX('Основной эфир'!$AI$3:$AI$1149,MATCH(B3,'Основной эфир'!$C$3:$C$1149,0)),"")} -> 3278.6885 | J3: {=IFERROR(INDEX('Основной эфир'!$AJ$3:$AJ$1149,MATCH(B3,'Основной эфир'!$C$3:$C$1149,0)),"")} -> 4000 | K3: =SUMIFS('Основной эфир'!$AK$3:$AK$1149,'Основной эфир'!$C$3:$C$1149,B3) -> 2078688.5 | L3: =SUMIFS('Основной эфир'!$AL$3:$AL$1149,'Основной эфир'!$C$3:$C$1149,B3) -> 2536000 | M3: 1
A4: Республика Башкортостан | B4: Стерлитамак | C4: =IFERROR(__xludf.DUMMYFUNCTION("COUNTUNIQUEIFS('Основной эфир'!E$3:E1004, 'Основной эфир'!C$3:C1004, B4, 'Основной эфир'!E$3:E1004, ""<>"") "),1.0) -> 1 | E4: =IFERROR(__xludf.DUMMYFUNCTION("COUNTUNIQUEIFS('Основной эфир'!I$3:I1004, 'Основной эфир'!C$3:C1004, B4, 'Основной эфир'!I$3:I1004, ""<>"") "),5.0) -> 5 | F4: =IFERROR(__xludf.DUMMYFUNCTION("COUNTUNIQUEIFS('Основной эфир'!J$3:J1004, 'Основной эфир'!C$3:C1004, B4, 'Основной эфир'!J$3:J1004, ""<>"") "),5.0) -> 5 | G4: =SUMIFS('Основной эфир'!$P$3:$P$1149,'Основной эфир'!$C$3:$C$1149,B4) -> 4690 | H4: =SUMIFS('Основной эфир'!$Q$3:$Q$1149,'Основной эфир'!$C$3:$C$1149,B4) -> 34 | I4: {=IFERROR(INDEX('Основной эфир'!$AI$3:$AI$1149,MATCH(B4,'Основной эфир'!$C$3:$C$1149,0)),"")} -> 3278.6885 | J4: {=IFERROR(INDEX('Основной эфир'!$AJ$3:$AJ$1149,MATCH(B4,'Основной эфир'!$C$3:$C$1149,0)),"")} -> 4000 | K4: =SUMIFS('Основной эфир'!$AK$3:$AK$1149,'Основной эфир'!$C$3:$C$1149,B4) -> 111475.41 | L4: =SUMIFS('Основной эфир'!$AL$3:$AL$1149,'Основной эфир'!$C$3:$C$1149,B4) -> 136000 | M4: 1
A5: Республика Башкортостан | B5: Нефтекамск | C5: =IFERROR(__xludf.DUMMYFUNCTION("COUNTUNIQUEIFS('Основной эфир'!E$3:E1004, 'Основной эфир'!C$3:C1004, B5, 'Основной эфир'!E$3:E1004, ""<>"") "),1.0) -> 1 | E5: =IFERROR(__xludf.DUMMYFUNCTION("COUNTUNIQUEIFS('Основной эфир'!I$3:I1004, 'Основной эфир'!C$3:C1004, B5, 'Основной эфир'!I$3:I1004, ""<>"") "),2.0) -> 2 | F5: =IFERROR(__xludf.DUMMYFUNCTION("COUNTUNIQUEIFS('Основной эфир'!J$3:J1004, 'Основной эфир'!C$3:C1004, B5, 'Основной эфир'!J$3:J1004, ""<>"") "),3.0) -> 3 | G5: =SUMIFS('Основной эфир'!$P$3:$P$1149,'Основной эфир'!$C$3:$C$1149,B5) -> 1968.4 | H5: =SUMIFS('Основной эфир'!$Q$3:$Q$1149,'Основной эфир'!$C$3:$C$1149,B5) -> 10 | I5: {=IFERROR(INDEX('Основной эфир'!$AI$3:$AI$1149,MATCH(B5,'Основной эфир'!$C$3:$C$1149,0)),"")} -> 3278.6885 | J5: {=IFERROR(INDEX('Основной эфир'!$AJ$3:$AJ$1149,MATCH(B5,'Основной эфир'!$C$3:$C$1149,0)),"")} -> 4000 | K5: =SUMIFS('Основной эфир'!$AK$3:$AK$1149,'Основной эфир'!$C$3:$C$1149,B5) -> 32786.885 | L5: =SUMIFS('Основной эфир'!$AL$3:$AL$1149,'Основной эфир'!$C$3:$C$1149,B5) -> 40000 | M5: 1
A6: Республика Башкортостан | B6: Октябрьский | C6: =IFERROR(__xludf.DUMMYFUNCTION("COUNTUNIQUEIFS('Основной эфир'!E$3:E1004, 'Основной эфир'!C$3:C1004, B6, 'Основной эфир'!E$3:E1004, ""<>"") "),1.0) -> 1 | E6: =IFERROR(__xludf.DUMMYFUNCTION("COUNTUNIQUEIFS('Основной эфир'!I$3:I1004, 'Основной эфир'!C$3:C1004, B6, 'Основной эфир'!I$3:I1004, ""<>"") "),1.0) -> 1 | F6: =IFERROR(__xludf.DUMMYFUNCTION("COUNTUNIQUEIFS('Основной эфир'!J$3:J1004, 'Основной эфир'!C$3:C1004, B6, 'Основной эфир'!J$3:J1004, ""<>"") "),1.0) -> 1 | G6: =SUMIFS('Основной эфир'!$P$3:$P$1149,'Основной эфир'!$C$3:$C$1149,B6) -> 658 | H6: =SUMIFS('Основной эфир'!$Q$3:$Q$1149,'Основной эфир'!$C$3:$C$1149,B6) -> 5 | I6: {=IFERROR(INDEX('Основной эфир'!$AI$3:$AI$1149,MATCH(B6,'Основной эфир'!$C$3:$C$1149,0)),"")} -> 3278.6885 | J6: {=IFERROR(INDEX('Основной эфир'!$AJ$3:$AJ$1149,MATCH(B6,'Основной эфир'!$C$3:$C$1149,0)),"")} -> 4000 | K6: =SUMIFS('Основной эфир'!$AK$3:$AK$1149,'Основной эфир'!$C$3:$C$1149,B6) -> 16393.443 | L6: =SUMIFS('Основной эфир'!$AL$3:$AL$1149,'Основной эфир'!$C$3:$C$1149,B6) -> 20000 | M6: 1
A7: Оренбургская область | B7: Оренбург | C7: =IFERROR(__xludf.DUMMYFUNCTION("COUNTUNIQUEIFS('Основной эфир'!E$3:E1004, 'Основной эфир'!C$3:C1004, B7, 'Основной эфир'!E$3:E1004, ""<>"") "),6.0) -> 6 | E7: =IFERROR(__xludf.DUMMYFUNCTION("COUNTUNIQUEIFS('Основной эфир'!I$3:I1004, 'Основной эфир'!C$3:C1004, B7, 'Основной эфир'!I$3:I1004, ""<>"") "),49.0) -> 49 | F7: =IFERROR(__xludf.DUMMYFUNCTION("COUNTUNIQUEIFS('Основной эфир'!J$3:J1004, 'Основной эфир'!C$3:C1004, B7, 'Основной эфир'!J$3:J1004, ""<>"") "),108.0) -> 108 | G7: =SUMIFS('Основной эфир'!$P$3:$P$1149,'Основной эфир'!$C$3:$C$1149,B7) -> 94802.4 | H7: =SUMIFS('Основной эфир'!$Q$3:$Q$1149,'Основной эфир'!$C$3:$C$1149,B7) -> 507 | I7: {=IFERROR(INDEX('Основной эфир'!$AI$3:$AI$1149,MATCH(B7,'Основной эфир'!$C$3:$C$1149,0)),"")} -> 3278.6885 | J7: {=IFERROR(INDEX('Основной эфир'!$AJ$3:$AJ$1149,MATCH(B7,'Основной эфир'!$C$3:$C$1149,0)),"")} -> 4000 | K7: =SUMIFS('Основной эфир'!$AK$3:$AK$1149,'Основной эфир'!$C$3:$C$1149,B7) -> 1662295.1 | L7: =SUMIFS('Основной эфир'!$AL$3:$AL$1149,'Основной эфир'!$C$3:$C$1149,B7) -> 2028000 | M7: 1
A8: Нижегородская область | B8: Нижний Новгород | C8: =IFERROR(__xludf.DUMMYFUNCTION("COUNTUNIQUEIFS('Основной эфир'!E$3:E1004, 'Основной эфир'!C$3:C1004, B8, 'Основной эфир'!E$3:E1004, ""<>"") "),7.0) -> 7 | E8: =IFERROR(__xludf.DUMMYFUNCTION("COUNTUNIQUEIFS('Основной эфир'!I$3:I1004, 'Основной эфир'!C$3:C1004, B8, 'Основной эфир'!I$3:I1004, ""<>"") "),71.0) -> 71 | F8: =IFERROR(__xludf.DUMMYFUNCTION("COUNTUNIQUEIFS('Основной эфир'!J$3:J1004, 'Основной эфир'!C$3:C1004, B8, 'Основной эфир'!J$3:J1004, ""<>"") "),112.0) -> 112 | G8: =SUMIFS('Основной эфир'!$P$3:$P$1149,'Основной эфир'!$C$3:$C$1149,B8) -> 54975.2 | H8: =SUMIFS('Основной эфир'!$Q$3:$Q$1149,'Основной эфир'!$C$3:$C$1149,B8) -> 400 | I8: {=IFERROR(INDEX('Основной эфир'!$AI$3:$AI$1149,MATCH(B8,'Основной эфир'!$C$3:$C$1149,0)),"")} -> 3278.6885 | J8: {=IFERROR(INDEX('Основной эфир'!$AJ$3:$AJ$1149,MATCH(B8,'Основной эфир'!$C$3:$C$1149,0)),"")} -> 4000 | K8: =SUMIFS('Основной эфир'!$AK$3:$AK$1149,'Основной эфир'!$C$3:$C$1149,B8) -> 1311475.4 | L8: =SUMIFS('Основной эфир'!$AL$3:$AL$1149,'Основной эфир'!$C$3:$C$1149,B8) -> 1600000 | M8: 1
A9: Республика Татарстан | B9: Казань | C9: =IFERROR(__xludf.DUMMYFUNCTION("COUNTUNIQUEIFS('Основной эфир'!E$3:E1004, 'Основной эфир'!C$3:C1004, B9, 'Основной эфир'!E$3:E1004, ""<>"") "),10.0) -> 10 | E9: =IFERROR(__xludf.DUMMYFUNCTION("COUNTUNIQUEIFS('Основной эфир'!I$3:I1004, 'Основной эфир'!C$3:C1004, B9, 'Основной эфир'!I$3:I1004, ""<>"") "),84.0) -> 84 | F9: =IFERROR(__xludf.DUMMYFUNCTION("COUNTUNIQUEIFS('Основной эфир'!J$3:J1004, 'Основной эфир'!C$3:C1004, B9, 'Основной эфир'!J$3:J1004, ""<>"") "),138.0) -> 138 | G9: =SUMIFS('Основной эфир'!$P$3:$P$1149,'Основной эфир'!$C$3:$C$1149,B9) -> 77268.8 | H9: =SUMIFS('Основной эфир'!$Q$3:$Q$1149,'Основной эфир'!$C$3:$C$1149,B9) -> 506 | I9: {=IFERROR(INDEX('Основной эфир'!$AI$3:$AI$1149,MATCH(B9,'Основной эфир'!$C$3:$C$1149,0)),"")} -> 3278.6885 | J9: {=IFERROR(INDEX('Основной эфир'!$AJ$3:$AJ$1149,MATCH(B9,'Основной эфир'!$C$3:$C$1149,0)),"")} -> 4000 | K9: =SUMIFS('Основной эфир'!$AK$3:$AK$1149,'Основной эфир'!$C$3:$C$1149,B9) -> 1659016.4 | L9: =SUMIFS('Основной эфир'!$AL$3:$AL$1149,'Основной эфир'!$C$3:$C$1149,B9) -> 2024000 | M9: 1
A10: Республика Татарстан | B10: Усады | C10: =IFERROR(__xludf.DUMMYFUNCTION("COUNTUNIQUEIFS('Основной эфир'!E$3:E1004, 'Основной эфир'!C$3:C1004, B10, 'Основной эфир'!E$3:E1004, ""<>"") "),1.0) -> 1 | E10: =IFERROR(__xludf.DUMMYFUNCTION("COUNTUNIQUEIFS('Основной эфир'!I$3:I1004, 'Основной эфир'!C$3:C1004, B10, 'Основной эфир'!I$3:I1004, ""<>"") "),1.0) -> 1 | F10: =IFERROR(__xludf.DUMMYFUNCTION("COUNTUNIQUEIFS('Основной эфир'!J$3:J1004, 'Основной эфир'!C$3:C1004, B10, 'Основной эфир'!J$3:J1004, ""<>"") "),7.0) -> 7 | G10: =SUMIFS('Основной эфир'!$P$3:$P$1149,'Основной эфир'!$C$3:$C$1149,B10) -> 2993.2 | H10: =SUMIFS('Основной эфир'!$Q$3:$Q$1149,'Основной эфир'!$C$3:$C$1149,B10) -> 12 | I10: {=IFERROR(INDEX('Основной эфир'!$AI$3:$AI$1149,MATCH(B10,'Основной эфир'!$C$3:$C$1149,0)),"")} -> 3278.6885 | J10: {=IFERROR(INDEX('Основной эфир'!$AJ$3:$AJ$1149,MATCH(B10,'Основной эфир'!$C$3:$C$1149,0)),"")} -> 4000 | K10: =SUMIFS('Основной эфир'!$AK$3:$AK$1149,'Основной эфир'!$C$3:$C$1149,B10) -> 39344.262 | L10: =SUMIFS('Основной эфир'!$AL$3:$AL$1149,'Основной эфир'!$C$3:$C$1149,B10) -> 48000 | M10: 1
A11: Московская область | B11: Путилково | C11: =IFERROR(__xludf.DUMMYFUNCTION("COUNTUNIQUEIFS('Основной эфир'!E$3:E1004, 'Основной эфир'!C$3:C1004, B11, 'Основной эфир'!E$3:E1004, ""<>"") "),1.0) -> 1 | E11: =IFERROR(__xludf.DUMMYFUNCTION("COUNTUNIQUEIFS('Основной эфир'!I$3:I1004, 'Основной эфир'!C$3:C1004, B11, 'Основной эфир'!I$3:I1004, ""<>"") "),4.0) -> 4 | F11: =IFERROR(__xludf.DUMMYFUNCTION("COUNTUNIQUEIFS('Основной эфир'!J$3:J1004, 'Основной эфир'!C$3:C1004, B11, 'Основной эфир'!J$3:J1004, ""<>"") "),11.0) -> 11 | G11: =SUMIFS('Основной эфир'!$P$3:$P$1149,'Основной эфир'!$C$3:$C$1149,B11) -> 11765.6 | H11: =SUMIFS('Основной эфир'!$Q$3:$Q$1149,'Основной эфир'!$C$3:$C$1149,B11) -> 48 | I11: {=IFERROR(INDEX('Основной эфир'!$AI$3:$AI$1149,MATCH(B11,'Основной эфир'!$C$3:$C$1149,0)),"")} -> 3278.6885 | J11: {=IFERROR(INDEX('Основной эфир'!$AJ$3:$AJ$1149,MATCH(B11,'Основной эфир'!$C$3:$C$1149,0)),"")} -> 4000 | K11: =SUMIFS('Основной эфир'!$AK$3:$AK$1149,'Основной эфир'!$C$3:$C$1149,B11) -> 157377.05 | L11: =SUMIFS('Основной эфир'!$AL$3:$AL$1149,'Основной эфир'!$C$3:$C$1149,B11) -> 192000 | M11: 1
A12: Московская область | B12: Одинцово | C12: =IFERROR(__xludf.DUMMYFUNCTION("COUNTUNIQUEIFS('Основной эфир'!E$3:E1004, 'Основной эфир'!C$3:C1004, B12, 'Основной эфир'!E$3:E1004, ""<>"") "),1.0) -> 1 | E12: =IFERROR(__xludf.DUMMYFUNCTION("COUNTUNIQUEIFS('Основной эфир'!I$3:I1004, 'Основной эфир'!C$3:C1004, B12, 'Основной эфир'!I$3:I1004, ""<>"") "),9.0) -> 9 | F12: =IFERROR(__xludf.DUMMYFUNCTION("COUNTUNIQUEIFS('Основной эфир'!J$3:J1004, 'Основной эфир'!C$3:C1004, B12, 'Основной эфир'!J$3:J1004, ""<>"") "),17.0) -> 17 | G12: =SUMIFS('Основной эфир'!$P$3:$P$1149,'Основной эфир'!$C$3:$C$1149,B12) -> 19171.6 | H12: =SUMIFS('Основной эфир'!$Q$3:$Q$1149,'Основной эфир'!$C$3:$C$1149,B12) -> 82 | I12: {=IFERROR(INDEX('Основной эфир'!$AI$3:$AI$1149,MATCH(B12,'Основной эфир'!$C$3:$C$1149,0)),"")} -> 3278.6885 | J12: {=IFERROR(INDEX('Основной эфир'!$AJ$3:$AJ$1149,MATCH(B12,'Основной эфир'!$C$3:$C$1149,0)),"")} -> 4000 | K12: =SUMIFS('Основной эфир'!$AK$3:$AK$1149,'Основной эфир'!$C$3:$C$1149,B12) -> 268852.46 | L12: =SUMIFS('Основной эфир'!$AL$3:$AL$1149,'Основной эфир'!$C$3:$C$1149,B12) -> 328000 | M12: 1
A13: Московская область | B13: Красногорск | C13: =IFERROR(__xludf.DUMMYFUNCTION("COUNTUNIQUEIFS('Основной эфир'!E$3:E1004, 'Основной эфир'!C$3:C1004, B13, 'Основной эфир'!E$3:E1004, ""<>"") "),1.0) -> 1 | E13: =IFERROR(__xludf.DUMMYFUNCTION("COUNTUNIQUEIFS('Основной эфир'!I$3:I1004, 'Основной эфир'!C$3:C1004, B13, 'Основной эфир'!I$3:I1004, ""<>"") "),3.0) -> 3 | F13: =IFERROR(__xludf.DUMMYFUNCTION("COUNTUNIQUEIFS('Основной эфир'!J$3:J1004, 'Основной эфир'!C$3:C1004, B13, 'Основной эфир'!J$3:J1004, ""<>"") "),5.0) -> 5 | G13: =SUMIFS('Основной эфир'!$P$3:$P$1149,'Основной эфир'!$C$3:$C$1149,B13) -> 12521.6 | H13: =SUMIFS('Основной эфир'!$Q$3:$Q$1149,'Основной эфир'!$C$3:$C$1149,B13) -> 28 | I13: {=IFERROR(INDEX('Основной эфир'!$AI$3:$AI$1149,MATCH(B13,'Основной эфир'!$C$3:$C$1149,0)),"")} -> 3278.6885 | J13: {=IFERROR(INDEX('Основной эфир'!$AJ$3:$AJ$1149,MATCH(B13,'Основной эфир'!$C$3:$C$1149,0)),"")} -> 4000 | K13: =SUMIFS('Основной эфир'!$AK$3:$AK$1149,'Основной эфир'!$C$3:$C$1149,B13) -> 91803.279 | L13: =SUMIFS('Основной эфир'!$AL$3:$AL$1149,'Основной эфир'!$C$3:$C$1149,B13) -> 112000 | M13: 1
A14: Московская область | B14: Мисайлово | C14: =IFERROR(__xludf.DUMMYFUNCTION("COUNTUNIQUEIFS('Основной эфир'!E$3:E1004, 'Основной эфир'!C$3:C1004, B14, 'Основной эфир'!E$3:E1004, ""<>"") "),1.0) -> 1 | E14: =IFERROR(__xludf.DUMMYFUNCTION("COUNTUNIQUEIFS('Основной эфир'!I$3:I1004, 'Основной эфир'!C$3:C1004, B14, 'Основной эфир'!I$3:I1004, ""<>"") "),9.0) -> 9 | F14: =IFERROR(__xludf.DUMMYFUNCTION("COUNTUNIQUEIFS('Основной эфир'!J$3:J1004, 'Основной эфир'!C$3:C1004, B14, 'Основной эфир'!J$3:J1004, ""<>"") "),28.0) -> 28 | G14: =SUMIFS('Основной эфир'!$P$3:$P$1149,'Основной эфир'!$C$3:$C$1149,B14) -> 27244 | H14: =SUMIFS('Основной эфир'!$Q$3:$Q$1149,'Основной эфир'!$C$3:$C$1149,B14) -> 84 | I14: {=IFERROR(INDEX('Основной эфир'!$AI$3:$AI$1149,MATCH(B14,'Основной эфир'!$C$3:$C$1149,0)),"")} -> 3278.6885 | J14: {=IFERROR(INDEX('Основной эфир'!$AJ$3:$AJ$1149,MATCH(B14,'Основной эфир'!$C$3:$C$1149,0)),"")} -> 4000 | K14: =SUMIFS('Основной эфир'!$AK$3:$AK$1149,'Основной эфир'!$C$3:$C$1149,B14) -> 275409.84 | L14: =SUMIFS('Основной эфир'!$AL$3:$AL$1149,'Основной эфир'!$C$3:$C$1149,B14) -> 336000 | M14: 1
A15: Московская область | B15: Внуково | C15: =IFERROR(__xludf.DUMMYFUNCTION("COUNTUNIQUEIFS('Основной эфир'!E$3:E1004, 'Основной эфир'!C$3:C1004, B15, 'Основной эфир'!E$3:E1004, ""<>"") "),1.0) -> 1 | E15: =IFERROR(__xludf.DUMMYFUNCTION("COUNTUNIQUEIFS('Основной эфир'!I$3:I1004, 'Основной эфир'!C$3:C1004, B15, 'Основной эфир'!I$3:I1004, ""<>"") "),4.0) -> 4 | F15: =IFERROR(__xludf.DUMMYFUNCTION("COUNTUNIQUEIFS('Основной эфир'!J$3:J1004, 'Основной эфир'!C$3:C1004, B15, 'Основной эфир'!J$3:J1004, ""<>"") "),16.0) -> 16 | G15: =SUMIFS('Основной эфир'!$P$3:$P$1149,'Основной эфир'!$C$3:$C$1149,B15) -> 9240 | H15: =SUMIFS('Основной эфир'!$Q$3:$Q$1149,'Основной эфир'!$C$3:$C$1149,B15) -> 29 | I15: {=IFERROR(INDEX('Основной эфир'!$AI$3:$AI$1149,MATCH(B15,'Основной эфир'!$C$3:$C$1149,0)),"")} -> 3278.6885 | J15: {=IFERROR(INDEX('Основной эфир'!$AJ$3:$AJ$1149,MATCH(B15,'Основной эфир'!$C$3:$C$1149,0)),"")} -> 4000 | K15: =SUMIFS('Основной эфир'!$AK$3:$AK$1149,'Основной эфир'!$C$3:$C$1149,B15) -> 95081.967 | L15: =SUMIFS('Основной эфир'!$AL$3:$AL$1149,'Основной эфир'!$C$3:$C$1149,B15) -> 116000 | M15: 1
A16: Московская область | B16: Щербинка | C16: =IFERROR(__xludf.DUMMYFUNCTION("COUNTUNIQUEIFS('Основной эфир'!E$3:E1004, 'Основной эфир'!C$3:C1004, B16, 'Основной эфир'!E$3:E1004, ""<>"") "),1.0) -> 1 | E16: =IFERROR(__xludf.DUMMYFUNCTION("COUNTUNIQUEIFS('Основной эфир'!I$3:I1004, 'Основной эфир'!C$3:C1004, B16, 'Основной эфир'!I$3:I1004, ""<>"") "),13.0) -> 13 | F16: =IFERROR(__xludf.DUMMYFUNCTION("COUNTUNIQUEIFS('Основной эфир'!J$3:J1004, 'Основной эфир'!C$3:C1004, B16, 'Основной эфир'!J$3:J1004, ""<>"") "),26.0) -> 26 | G16: =SUMIFS('Основной эфир'!$P$3:$P$1149,'Основной эфир'!$C$3:$C$1149,B16) -> 33625.2 | H16: =SUMIFS('Основной эфир'!$Q$3:$Q$1149,'Основной эфир'!$C$3:$C$1149,B16) -> 102 | I16: {=IFERROR(INDEX('Основной эфир'!$AI$3:$AI$1149,MATCH(B16,'Основной эфир'!$C$3:$C$1149,0)),"")} -> 3278.6885 | J16: {=IFERROR(INDEX('Основной эфир'!$AJ$3:$AJ$1149,MATCH(B16,'Основной эфир'!$C$3:$C$1149,0)),"")} -> 4000 | K16: =SUMIFS('Основной эфир'!$AK$3:$AK$1149,'Основной эфир'!$C$3:$C$1149,B16) -> 334426.23 | L16: =SUMIFS('Основной эфир'!$AL$3:$AL$1149,'Основной эфир'!$C$3:$C$1149,B16) -> 408000 | M16: 1
A17: Всего | B17: =COUNTA(B3:B16) -> 14 | C17: =IFERROR(__xludf.DUMMYFUNCTION("COUNTUNIQUEIFS('Основной эфир'!E$3:E1004, 'Основной эфир'!C$3:C1004, B17, 'Основной эфир'!E$3:E1004, ""<>"") "),0.0) -> 0 | E17: =SUM(E3:E16) -> 377 | F17: =SUM(F3:F16) -> 653 | H17: =SUM(H3:H16) -> 2481 | K17: =SUM(K3:K16) -> 8134426.2 | L17: =SUM(L3:L16) -> 9924000

Sheet Основной эфир
D1: Прайс на размещение рекламного ролика
A2: GID | B2: Регион | C2: Город | D2: Район | E2: Название пакета | F2: Категория ЖК | G2: Дата застройки экранов | H2: Класс жилья | I2: Наименование ЖК | J2: Адрес | K2: Коррдинаты (широта, долгота) | M2: Год сдачи дома | N2: Этажность | O2: Количество квартир | P2: Количество жильцов | Q2: Всего экранов | R2: Число экранов в холле | S2: Всего холлов в доме | T2: Число экранов в лифте | U2: Всего лифтов в доме | V2: Тип экрана | W2: Способ показа | X2: Формат | Y2: Хронометраж (сек) | Z2: Блок | AA2: Кол-во показов в сутки/1 экран (сек) | AB2: Период/дней | AC2: Кол-во показов в ЖК/период | AD2: Частота контакта рекламы c 1 жителем (Frequency) | AE2: Количество контактов с рекламой (OTS) | AF2: Стоимость 1000 контактов (CPT) с НДС для Федерального и крупного бизнеса | AG2: ФО/скрин с камеры | AH2: Фото | AI2: Цена за размещение на 1 экране/месяц руб. без НДС | AJ2: Цена за размещение на 1 экране/месяц руб. в т.ч НДС 22% | AK2: Стоимость размещения в 1 доме/1 месяц, руб. без НДС | AL2: Стоимость размещения в 1 доме/1 месяц, руб. в т.ч.НДС 22%
A3: U1 | B3: Республика Башкортостан | C3: Уфа | D3: Ленинский | E3: Проспект | F3: А | G3: 45839 | H3: Бизнес | I3: ЖК Видинеевский | J3: улица Пархоменко, 156Б | K3: 54.743697 | L3: 55.969246 | M3: 2021 | N3: 14 | O3: 412 | P3: =O3*2.8 -> 1153.6 | Q3: 2 | R3: 1 | S3: 3 | T3: 1 | U3: 6 | V3: Горизонтальный 4*3 | W3: Digital (без звука) | X3: видеоролик | Y3: 10 | Z3: 150 | AA3: 576 | AB3: 31 | AC3: =Q3*AA3*AB3 -> 35712 | AD3: =AE3/P3 -> 5.1942222 | AE3: =((P3*2.6*R3/S3/2)*30/Z3+(P3*2.6*T3/U3)*N3*2/Z3)*AB3 -> 5992.0548 | AF3: =AL3/AE3*1000 -> 1335.1013 | AG3: 1 | AH3: https://ibb.co/1S8hzvX | AI3: =AJ3/1.22 -> 3278.6885 | AJ3: 4000 | AK3: =AI3*Q3 -> 6557.377 | AL3: =AK3*1.22 -> 8000
A4: U1 | B4: Республика Башкортостан | C4: Уфа | D4: Ленинский | E4: Проспект | F4: А | G4: 45839 | H4: Бизнес | I4: ЖК Видинеевский | J4: улица Пархоменко, 156В | K4: 54.744659 | L4: 55.969713 | M4: 2019 | N4: 26 | O4: 232 | P4: =O4*2.8 -> 649.6 | Q4: 2 | R4: 1 | S4: 1 | T4: 1 | U4: 3 | V4: Горизонтальный 4*3 | W4: Digital (без звука) | X4: видеоролик | Y4: 10 | Z4: 150 | AA4: 576 | AB4: 31 | AC4: =Q4*AA4*AB4 -> 35712 | AD4: =AE4/P4 -> 17.373778 | AE4: =((P4*2.6*R4/S4/2)*30/Z4+(P4*2.6*T4/U4)*N4*2/Z4)*AB4 -> 11286.006 | AF4: =AL4/AE4*1000 -> 708.84243 | AG4: 1 | AH4: https://ibb.co/1pfqR3G | AI4: =AJ4/1.22 -> 3278.6885 | AJ4: 4000 | AK4: =AI4*Q4 -> 6557.377 | AL4: =AK4*1.22 -> 8000
A5: U1 | B5: Республика Башкортостан | C5: Уфа | D5: Ленинский | E5: Проспект | F5: А | G5: 45839 | H5: Бизнес | I5: ЖК Видинеевский | J5: улица Пархоменко, 156Г | K5: 54.744939 | L5: 55.970603 | M5: 2023 | N5: 25 | O5: 173 | P5: =O5*2.8 -> 484.4 | Q5: 1 | R5: 0 | S5: 1 | T5: 1 | U5: 3 | V5: Горизонтальный 4*3 | W5: Digital (без звука) | X5: видеоролик | Y5: 10 | Z5: 150 | AA5: 576 | AB5: 31 | AC5: =Q5*AA5*AB5 -> 17856 | AD5: =AE5/P5 -> 8.9555556 | AE5: =((P5*2.6*R5/S5/2)*30/Z5+(P5*2.6*T5/U5)*N5*2/Z5)*AB5 -> 4338.0711 | AF5: =AL5/AE5*1000 -> 922.06879 | AG5: 1 | AI5: =AJ5/1.22 -> 3278.6885 | AJ5: 4000 | AK5: =AI5*Q5 -> 3278.6885 | AL5: =AK5*1.22 -> 4000
A6: U1 | B6: Республика Башкортостан | C6: Уфа | D6: Ленинский | E6: Проспект | F6: А | G6: 45839 | H6: Бизнес | I6: ЖК Видинеевский | J6: лица Пархоменко, 156Е | K6: 54.744482 | L6: 55.972408 | M6: 2025 | N6: 26 | O6: 233 | P6: =O6*2.8 -> 652.4 | Q6: 3 | R6: 0 | S6: 1 | T6: 3 | U6: 3 | V6: Горизонтальный 4*3 | W6: Digital (без звука) | X6: видеоролик | Y6: 10 | Z6: 150 | AA6: 576 | AB6: 31 | AC6: =Q6*AA6*AB6 -> 53568 | AD6: =AE6/P6 -> 27.941333 | AE6: =((P6*2.6*R6/S6/2)*30/Z6+(P6*2.6*T6/U6)*N6*2/Z6)*AB6 -> 18228.926 | AF6: =AL6/AE6*1000 -> 658.29441 | AG6: 1 | AI6: =AJ6/1.22 -> 3278.6885 | AJ6: 4000 | AK6: =AI6*Q6 -> 9836.0656 | AL6: =AK6*1.22 -> 12000
A7: U1 | B7: Республика Башкортостан | C7: Уфа | D7: Ленинский | E7: Проспект | F7: А | G7: 45839 | H7: Бизнес | I7: ЖК Видинеевский | J7: улица Пархоменко, 156Ж | K7: 54.743999 | L7: 55.972094 | M7: 2024 | N7: 15 | O7: 289 | P7: =O7*2.8 -> 809.2 | Q7: 4 | R7: 2 | S7: 1 | T7: 2 | U7: 4 | V7: Горизонтальный 4*3 | W7: Digital (без звука) | X7: видеоролик | Y7: 10 | Z7: 150 | AA7: 576 | AB7: 31 | AC7: =Q7*AA7*AB7 -> 71424 | AD7: =AE7/P7 -> 24.18 | AE7: =((P7*2.6*R7/S7/2)*30/Z7+(P7*2.6*T7/U7)*N7*2/Z7)*AB7 -> 19566.456 | AF7: =AL7/AE7*1000 -> 817.72601 | AG7: 1 | AI7: =AJ7/1.22 -> 3278.6885 | AJ7: 4000 | AK7: =AI7*Q7 -> 13114.754 | AL7: =AK7*1.22 -> 16000
A8: U2 | B8: Республика Башкортостан | C8: Уфа | D8: Кировский | E8: Зеленая Роща 2 | F8: Б | G8: 45985 | H8: Комфорт | I8: ЖК Южный | J8: улица Генерала Рыленко, 8 | K8: 54.695476 | L8: 55.989638 | M8: 2021 | N8: 28 | O8: 301 | P8: =O8*2.8 -> 842.8 | Q8: 3 | R8: 1 | S8: 1 | T8: 2 | U8: 4 | V8: Горизонтальный 4*3 | W8: Digital (без звука) | X8: видеоролик | Y8: 10 | Z8: 150 | AA8: 576 | AB8: 31 | AC8: =Q8*AA8*AB8 -> 53568 | AD8: =AE8/P8 -> 23.105333 | AE8: =((P8*2.6*R8/S8/2)*30/Z8+(P8*2.6*T8/U8)*N8*2/Z8)*AB8 -> 19473.175 | AF8: =AL8/AE8*1000 -> 616.23233 | AG8: 1 | AI8: =AJ8/1.22 -> 3278.6885 | AJ8: 4000 | AK8: =AI8*Q8 -> 9836.0656 | AL8: =AK8*1.22 -> 12000
A9: U3 | B9: Республика Башкортостан | C9: Уфа | D9: Кировский | E9: Центр | F9: А | G9: 45950 | H9: Бизнес | I9: ЖК Выбор первых | J9: улица Айская, 61 | K9: 54.727375 | L9: 55.976172 | M9: 2024 | N9: 10 | O9: 329 | P9: =O9*2.8 -> 921.2 | Q9: 5 | R9: 0 | S9: 5 | T9: 5 | U9: 5 | V9: Горизонтальный 4*3 | W9: Digital (без звука) | X9: видеоролик | Y9: 10 | Z9: 150 | AA9: 576 | AB9: 31 | AC9: =Q9*AA9*AB9 -> 89280 | AD9: =AE9/P9 -> 10.746667 | AE9: =((P9*2.6*R9/S9/2)*30/Z9+(P9*2.6*T9/U9)*N9*2/Z9)*AB9 -> 9899.8293 | AF9: =AL9/AE9*1000 -> 2020.2368 | AG9: 1 | AI9: =AJ9/1.22 -> 3278.6885 | AJ9: 4000 | AK9: =AI9*Q9 -> 16393.443 | AL9: =AK9*1.22 -> 20000
A10: U4 | B10: Республика Башкортостан | C10: Уфа | D10: Калининский | E10: Инорс_Сипайлово | F10: Б | G10: 45961 | H10: Стандарт | I10: ЖК Акварель | J10: улица Лётчика Кобелева, 1 | K10: 54.778409 | L10: 56.137887 | M10: 2023 | N10: 19 | O10: 102 | P10: =O10*2.8 -> 285.6 | Q10: 1 | R10: 1 | S10: 8 | T10: 0 | U10: 16 | V10: Горизонтальный 4*3 | W10: Digital (без звука) | X10: видеоролик | Y10: 10 | Z10: 150 | AA10: 576 | AB10: 31 | AC10: =Q10*AA10*AB10 -> 17856 | AD10: =AE10/P10 -> 1.0075 | AE10: =((P10*2.6*R10/S10/2)*30/Z10+(P10*2.6*T10/U10)*N10*2/Z10)*AB10 -> 287.742 | AF10: =AL10/AE10*1000 -> 13901.342 | AG10: 1 | AI10: =AJ10/1.22 -> 3278.6885 | AJ10: 4000 | AK10: =AI10*Q10 -> 3278.6885 | AL10: =AK10*1.22 -> 4000
A11: U4 | B11: Республика Башкортостан | C11: Уфа | D11: Калининский | E11: Инорс_Сипайлово | F11: Б | G11: 45961 | H11: Стандарт | I11: ЖК Акварель | J11: улица Лётчика Кобелева, 3/3 | K11: 54.778180 | L11: 56.134411 | M11: 2018 | N11: 27 | O11: 338 | P11: =O11*2.8 -> 946.4 | Q11: 1 | R11: 1 | S11: 1 | T11: 0 | U11: 3 | V11: Горизонтальный 4*3 | W11: Digital (без звука) | X11: видеоролик | Y11: 10 | Z11: 150 | AA11: 576 | AB11: 31 | AC11: =Q11*AA11*AB11 -> 17856 | AD11: =AE11/P11 -> 8.06 | AE11: =((P11*2.6*R11/S11/2)*30/Z11+(P11*2.6*T11/U11)*N11*2/Z11)*AB11 -> 7627.984 | AF11: =AL11/AE11*1000 -> 524.38495 | AG11: 1 | AI11: =AJ11/1.22 -> 3278.6885 | AJ11: 4000 | AK11: =AI11*Q11 -> 3278.6885 | AL11: =AK11*1.22 -> 4000
A12: U4 | B12: Республика Башкортостан | C12: Уфа | D12: Калининский | E12: Инорс_Сипайлово | F12: Б | G12: 45961 | H12: Стандарт | I12: ЖК Акварель | J12: улица Ферина, 33 | K12: 54.777126 | L12: 56.132030 | M12: 2017 | N12: 18 | O12: 187 | P12: =O12*2.8 -> 523.6 | Q12: 2 | R12: 0 | S12: 2 | T12: 2 | U12: 4 | V12: Вертикальный 4*3 | W12: Digital (без звука) | X12: видеоролик | Y12: 10 | Z12: 150 | AA12: 576 | AB12: 31 | AC12: =Q12*AA12*AB12 -> 35712 | AD12: =AE12/P12 -> 9.672 | AE12: =((P12*2.6*R12/S12/2)*30/Z12+(P12*2.6*T12/U12)*N12*2/Z12)*AB12 -> 5064.2592 | AF12: =AL12/AE12*1000 -> 1579.698 | AG12: 1 | AI12: =AJ12/1.22 -> 3278.6885 | AJ12: 4000 | AK12: =AI12*Q12 -> 6557.377 | AL12: =AK12*1.22 -> 8000
A13: U5 | B13: Республика Башкортостан | C13: Уфа | D13: Ленинский | E13: Центр | F13: Б | G13: 45961 | H13: Бизнес | I13: ЖК Старый центр | J13: улица Чернышевского, 26 | K13: 54.731545 | L13: 55.928831 | M13: 2023 | N13: 19 | O13: 321 | P13: =O13*2.8 -> 898.8 | Q13: 2 | R13: 2 | S13: 2 | T13: 0 | U13: 4 | V13: Горизонтальный 4*3 | W13: Digital (без звука) | X13: видеоролик | Y13: 10 | Z13: 150 | AA13: 576 | AB13: 31 | AC13: =Q13*AA13*AB13 -> 35712 | AD13: =AE13/P13 -> 8.06 | AE13: =((P13*2.6*R13/S13/2)*30/Z13+(P13*2.6*T13/U13)*N13*2/Z13)*AB13 -> 7244.328 | AF13: =AL13/AE13*1000 -> 1104.3122 | AG13: 1 | AI13: =AJ13/1.22 -> 3278.6885 | AJ13: 4000 | AK13: =AI13*Q13 -> 6557.377 | AL13: =AK13*1.22 -> 8000
A14: U5 | B14: Республика Башкортостан | C14: Уфа | D14: Ленинский | E14: Центр | F14: Б | G14: 45961 | H14: Бизнес | I14: ЖК Старый центр | J14: улица Коммунистическая, 15 | K14: 54.729512 | L14: 55.929083 | M14: 2020 | N14: 15 | O14: 151 | P14: =O14*2.8 -> 422.8 | Q14: 2 | R14: 2 | S14: 2 | T14: 0 | U14: 4 | V14: Горизонтальный 4*3 | W14: Digital (без звука) | X14: видеоролик | Y14: 10 | Z14: 150 | AA14: 576 | AB14: 31 | AC14: =Q14*AA14*AB14 -> 35712 | AD14: =AE14/P14 -> 8.06 | AE14: =((P14*2.6*R14/S14/2)*30/Z14+(P14*2.6*T14/U14)*N14*2/Z14)*AB14 -> 3407.768 | AF14: =AL14/AE14*1000 -> 2347.5777 | AG14: 1 | AI14: =AJ14/1.22 -> 3278.6885 | AJ14: 4000 | AK14: =AI14*Q14 -> 6557.377 | AL14: =AK14*1.22 -> 8000
A15: U5 | B15: Республика Башкортостан | C15: Уфа | D15: Ленинский | E15: Центр | F15: Б | G15: 45961 | H15: Бизнес | I15: ЖК Старый центр | J15: улица Чернышевского, 28 | K15: 54.731326 | L15: 55.929774 | M15: 2012 | N15: 18 | O15: 111 | P15: =O15*2.8 -> 310.8 | Q15: 1 | R15: 1 | S15: 1 | T15: 0 | U15: 2 | V15: Горизонтальный 4*3 | W15: Digital (без звука) | X15: видеоролик | Y15: 10 | Z15: 150 | AA15: 576 | AB15: 31 | AC15: =Q15*AA15*AB15 -> 17856 | AD15: =AE15/P15 -> 8.06 | AE15: =((P15*2.6*R15/S15/2)*30/Z15+(P15*2.6*T15/U15)*N15*2/Z15)*AB15 -> 2505.048 | AF15: =AL15/AE15*1000 -> 1596.7758 | AG15: 1 | AI15: =AJ15/1.22 -> 3278.6885 | AJ15: 4000 | AK15: =AI15*Q15 -> 3278.6885 | AL15: =AK15*1.22 -> 4000
A16: U5 | B16: Республика Башкортостан | C16: Уфа | D16: Ленинский | E16: Центр | F16: Б | G16: 45961 | H16: Бизнес | I16: ЖК Старый центр | J16: улица Коммунистическая, 11/1 | K16: 54.730157 | L16: 55.927978 | M16: 2018 | N16: 27 | O16: 271 | P16: =O16*2.8 -> 758.8 | Q16: 1 | R16: 1 | S16: 1 | T16: 0 | U16: 3 | V16: Горизонтальный 4*3 | W16: Digital (без звука) | X16: видеоролик | Y16: 10 | Z16: 150 | AA16: 576 | AB16: 31 | AC16: =Q16*AA16*AB16 -> 17856 | AD16: =AE16/P16 -> 8.06 | AE16: =((P16*2.6*R16/S16/2)*30/Z16+(P16*2.6*T16/U16)*N16*2/Z16)*AB16 -> 6115.928 | AF16: =AL16/AE16*1000 -> 654.02994 | AG16: 1 | AI16: =AJ16/1.22 -> 3278.6885 | AJ16: 4000 | AK16: =AI16*Q16 -> 3278.6885 | AL16: =AK16*1.22 -> 4000
... A131: U79 | B131: Республика Башкортостан | C131: Уфа | D131: Кировский | E131: Зеленая Роща 2 | F131: А | G131: 46171 | H131: Комфорт | I131: квартал Кузнецовский затон | J131: улица Просвещения, 11/1 | K131: 54.689997 | L131: 55.972204 | M131: 2019 | N131: 11 | O131: 70 | P131: =O131*2.8 -> 196 | Q131: 1 | R131: 0 | S131: 1 | T131: 1 | U131: 1 | V131: Вертикальный 4*3 | W131: Digital (без звука) | X131: видеоролик | Y131: 10 | Z131: 150 | AA131: 576 | AB131: 31 | AC131: =Q131*AA131*AB131 -> 17856 | AD131: =AE131/P131 -> 11.821333 | AE131: =((P131*2.6*R131/S131/2)*30/Z131+(P131*2.6*T131/U131)*N131*2/Z131)*AB131 -> 2316.9813 | AF131: =AL131/AE131*1000 -> 1726.3842 | AG131: 1 | AI131: =AJ131/1.22 -> 3278.6885 | AJ131: 4000 | AK131: =AI131*Q131 -> 3278.6885 | AL131: =AK131*1.22 -> 4000
A132: U79 | B132: Республика Башкортостан | C132: Уфа | D132: Кировский | E132: Зеленая Роща 2 | F132: А | G132: 46244 | H132: Комфорт | I132: квартал Кузнецовский затон | J132: улица Бородинская, 20/1 | K132: 54.686208, 55.984572 | M132: 2023 | N132: 12 | O132: 158 | P132: =O132*2.8 -> 442.4 | Q132: 2 | R132: 0 | S132: 1 | T132: 2 | U132: 2 | V132: Вертикальный 4*3 | W132: Digital (без звука) | X132: видеоролик | Y132: 10 | Z132: 150 | AA132: 576 | AB132: 31 | AC132: =Q132*AA132*AB132 -> 35712 | AD132: =AE132/P132 -> 12.896 | AE132: =((P132*2.6*R132/S132/2)*30/Z132+(P132*2.6*T132/U132)*N132*2/Z132)*AB132 -> 5705.1904 | AF132: =AL132/AE132*1000 -> 1402.2319 | AG132: 1 | AI132: =AJ132/1.22 -> 3278.6885 | AJ132: 4000 | AK132: =AI132*Q132 -> 6557.377 | AL132: =AK132*1.22 -> 8000
A133: U80 | B133: Республика Башкортостан | C133: Уфа | D133: Ленинский | E133: Ленинский 1 Затон_мкрн. 8 Марта | F133: А | G133: 46183 | H133: Стандарт | I133: Квартал Летчиков | J133: улица Летчиков, 16/1 | K133: 54.795296 | L133: 55.867126 | M133: 2014 | N133: 18 | O133: 90 | P133: =O133*2.8 -> 252 | Q133: 2 | R133: 0 | S133: 1 | T133: 2 | U133: 2 | V133: Вертикальный 4*3 | W133: Digital (без звука) | X133: видеоролик | Y133: 10 | Z133: 150 | AA133: 576 | AB133: 31 | AC133: =Q133*AA133*AB133 -> 35712 | AD133: =AE133/P133 -> 19.344 | AE133: =((P133*2.6*R133/S133/2)*30/Z133+(P133*2.6*T133/U133)*N133*2/Z133)*AB133 -> 4874.688 | AF133: =AL133/AE133*1000 -> 1641.1307 | AG133: 1 | AI133: =AJ133/1.22 -> 3278.6885 | AJ133: 4000 | AK133: =AI133*Q133 -> 6557.377 | AL133: =AK133*1.22 -> 8000
A134: U80 | B134: Республика Башкортостан | C134: Уфа | D134: Ленинский | E134: Ленинский 1 Затон_мкрн. 8 Марта | F134: А | G134: 46183 | H134: Стандарт | I134: Квартал Летчиков | J134: улица Летчиков, 18 | K134: 54.79523 | L134: 55.868527 | M134: 2013 | N134: 14 | O134: 154 | P134: =O134*2.8 -> 431.2 | Q134: 3 | R134: 0 | S134: 3 | T134: 3 | U134: 6 | V134: Вертикальный 4*3 | W134: Digital (без звука) | X134: видеоролик | Y134: 10 | Z134: 150 | AA134: 576 | AB134: 31 | AC134: =Q134*AA134*AB134 -> 53568 | AD134: =AE134/P134 -> 7.5226667 | AE134: =((P134*2.6*R134/S134/2)*30/Z134+(P134*2.6*T134/U134)*N134*2/Z134)*AB134 -> 3243.7739 | AF134: =AL134/AE134*1000 -> 3699.3947 | AG134: 1 | AI134: =AJ134/1.22 -> 3278.6885 | AJ134: 4000 | AK134: =AI134*Q134 -> 9836.0656 | AL134: =AK134*1.22 -> 12000
A135: U81 | B135: Республика Башкортостан | C135: Уфа | D135: Октябрьский | E135: Инорс_Сипайлово | F135: А | G135: 46168 | H135: Комфорт | I135: Квартал Олимп | J135: улица Маршала Жукова, 4/4 | K135: 54.765952 | L135: 56.051225 | M135: 2002 | N135: 10 | O135: 150 | P135: =O135*2.8 -> 420 | Q135: 3 | R135: 0 | S135: 3 | T135: 3 | U135: 3 | V135: Вертикальный 4*3 | W135: Digital (без звука) | X135: видеоролик | Y135: 10 | Z135: 150 | AA135: 576 | AB135: 31 | AC135: =Q135*AA135*AB135 -> 53568 | AD135: =AE135/P135 -> 10.746667 | AE135: =((P135*2.6*R135/S135/2)*30/Z135+(P135*2.6*T135/U135)*N135*2/Z135)*AB135 -> 4513.6 | AF135: =AL135/AE135*1000 -> 2658.6317 | AG135: 1 | AI135: =AJ135/1.22 -> 3278.6885 | AJ135: 4000 | AK135: =AI135*Q135 -> 9836.0656 | AL135: =AK135*1.22 -> 12000
A136: U82 | B136: Республика Башкортостан | C136: Уфа | D136: Октябрьский | E136: Инорс_Сипайлово | F136: А | G136: 46196 | H136: Комфорт | I136: Квартал Олимп 2 | J136: улица Маршала Жукова, 4/1 | K136: 54.767256 | L136: 56.053738 | M136: 1995 | N136: 10 | O136: 290 | P136: =O136*2.8 -> 812 | Q136: 8 | R136: 0 | S136: 8 | T136: 8 | U136: 8 | V136: Вертикальный 4*3 | W136: Digital (без звука) | X136: видеоролик | Y136: 10 | Z136: 150 | AA136: 576 | AB136: 31 | AC136: =Q136*AA136*AB136 -> 142848 | AD136: =AE136/P136 -> 10.746667 | AE136: =((P136*2.6*R136/S136/2)*30/Z136+(P136*2.6*T136/U136)*N136*2/Z136)*AB136 -> 8726.2933 | AF136: =AL136/AE136*1000 -> 3667.0782 | AG136: 1 | AI136: =AJ136/1.22 -> 3278.6885 | AJ136: 4000 | AK136: =AI136*Q136 -> 26229.508 | AL136: =AK136*1.22 -> 32000
A137: U83 | B137: Республика Башкортостан | C137: Уфа | D137: Октябрьский | E137: Инорс_Сипайлово | F137: А | G137: 46186 | H137: Комфорт | I137: Квартал Олимп 3 | J137: улица Юрия Гагарина, 10/2 | K137: 54.763763 | L137: 56.050715 | M137: 2001 | N137: 9 | O137: 207 | P137: =O137*2.8 -> 579.6 | Q137: 7 | R137: 0 | S137: 7 | T137: 7 | U137: 7 | V137: Вертикальный 4*3 | W137: Digital (без звука) | X137: видеоролик | Y137: 10 | Z137: 150 | AA137: 576 | AB137: 31 | AC137: =Q137*AA137*AB137 -> 124992 | AD137: =AE137/P137 -> 9.672 | AE137: =((P137*2.6*R137/S137/2)*30/Z137+(P137*2.6*T137/U137)*N137*2/Z137)*AB137 -> 5605.8912 | AF137: =AL137/AE137*1000 -> 4994.7455 | AG137: 1 | AI137: =AJ137/1.22 -> 3278.6885 | AJ137: 4000 | AK137: =AI137*Q137 -> 22950.82 | AL137: =AK137*1.22 -> 28000
A138: U84 | B138: Республика Башкортостан | C138: Уфа | D138: Октябрьский | E138: Инорс_Сипайлово | F138: Б | G138: 46188 | H138: Комфорт | I138: Квартал Маяк | J138: улица Маршала Жукова, 3/2 | K138: 54.766198 | L138: 56.047695 | M138: 2007 | N138: 18 | O138: 80 | P138: =O138*2.8 -> 224 | Q138: 2 | R138: 0 | S138: 1 | T138: 2 | U138: 2 | V138: Вертикальный 4*3 | W138: Digital (без звука) | X138: видеоролик | Y138: 10 | Z138: 150 | AA138: 576 | AB138: 31 | AC138: =Q138*AA138*AB138 -> 35712 | AD138: =AE138/P138 -> 19.344 | AE138: =((P138*2.6*R138/S138/2)*30/Z138+(P138*2.6*T138/U138)*N138*2/Z138)*AB138 -> 4333.056 | AF138: =AL138/AE138*1000 -> 1846.272 | AG138: 1 | AI138: =AJ138/1.22 -> 3278.6885 | AJ138: 4000 | AK138: =AI138*Q138 -> 6557.377 | AL138: =AK138*1.22 -> 8000
A139: U85 | B139: Республика Башкортостан | C139: Уфа | D139: Кировский | E139: Зеленая Роща 2 | F139: Б | G139: 46191 | H139: Комфорт | I139: ЖК Южный 2 | J139: улица Загира Исмагилова, 16/1 | K139: 54.698573 | L139: 55.982071 | M139: 2009 | N139: 9 | O139: 71 | P139: =O139*2.8 -> 198.8 | Q139: 2 | R139: 0 | S139: 2 | T139: 2 | U139: 2 | V139: Вертикальный 4*3 | W139: Digital (без звука) | X139: видеоролик | Y139: 10 | Z139: 150 | AA139: 576 | AB139: 31 | AC139: =Q139*AA139*AB139 -> 35712 | AD139: =AE139/P139 -> 9.672 | AE139: =((P139*2.6*R139/S139/2)*30/Z139+(P139*2.6*T139/U139)*N139*2/Z139)*AB139 -> 1922.7936 | AF139: =AL139/AE139*1000 -> 4160.613 | AG139: 1 | AI139: =AJ139/1.22 -> 3278.6885 | AJ139: 4000 | AK139: =AI139*Q139 -> 6557.377 | AL139: =AK139*1.22 -> 8000
A140: U85 | B140: Республика Башкортостан | C140: Уфа | D140: Кировский | E140: Зеленая Роща 2 | F140: Б | G140: 46191 | H140: Комфорт | I140: ЖК Южный 2 | J140: улица Загира Исмагилова, д. 18 | K140: 54.698718 | L140: 55.980256 | M140: 2012 | N140: 13 | O140: 148 | P140: =O140*2.8 -> 414.4 | Q140: 2 | R140: 0 | S140: 2 | T140: 2 | U140: 4 | V140: Вертикальный 4*3 | W140: Digital (без звука) | X140: видеоролик | Y140: 10 | Z140: 150 | AA140: 576 | AB140: 31 | AC140: =Q140*AA140*AB140 -> 35712 | AD140: =AE140/P140 -> 6.9853333 | AE140: =((P140*2.6*R140/S140/2)*30/Z140+(P140*2.6*T140/U140)*N140*2/Z140)*AB140 -> 2894.7221 | AF140: =AL140/AE140*1000 -> 2763.6504 | AG140: 1 | AI140: =AJ140/1.22 -> 3278.6885 | AJ140: 4000 | AK140: =AI140*Q140 -> 6557.377 | AL140: =AK140*1.22 -> 8000
A141: U86 | B141: Республика Башкортостан | C141: Уфа | D141: Дёмский | E141: Дёмский_мкрн. Цветы Башкирии | F141: А | G141: 46191 | H141: Комфорт | I141: ЖК Яркий Квартал Париж 1 | J141: Яркий бульвар, 10 | K141: 54.695817 | L141: 55.859804 | M141: 2022 | N141: 19 | O141: 204 | P141: =O141*2.8 -> 571.2 | Q141: 3 | R141: 0 | S141: 1 | T141: 3 | U141: 3 | V141: Вертикальный 4*3 | W141: Digital (без звука) | X141: видеоролик | Y141: 10 | Z141: 150 | AA141: 576 | AB141: 31 | AC141: =Q141*AA141*AB141 -> 53568 | AD141: =AE141/P141 -> 20.418667 | AE141: =((P141*2.6*R141/S141/2)*30/Z141+(P141*2.6*T141/U141)*N141*2/Z141)*AB141 -> 11663.142 | AF141: =AL141/AE141*1000 -> 1028.8822 | AG141: 1 | AI141: =AJ141/1.22 -> 3278.6885 | AJ141: 4000 | AK141: =AI141*Q141 -> 9836.0656 | AL141: =AK141*1.22 -> 12000
A142: U87 | B142: Республика Башкортостан | C142: Уфа | D142: Дёмский | E142: Дёмский_мкрн. Цветы Башкирии | F142: А | G142: 46217 | H142: Комфорт | I142: ЖК Яркий Квартал Париж 2 | J142: улица Евгения Столярова, 13 | K142: 54.695185 | L142: 55.857586 | M142: 2025 | N142: 26 | O142: 288 | P142: =O142*2.8 -> 806.4 | Q142: 3 | R142: 0 | S142: 1 | T142: 3 | U142: 4 | V142: Вертикальный 4*3 | W142: Digital (без звука) | X142: видеоролик | Y142: 10 | Z142: 150 | AA142: 576 | AB142: 31 | AC142: =Q142*AA142*AB142 -> 53568 | AD142: =AE142/P142 -> 20.956 | AE142: =((P142*2.6*R142/S142/2)*30/Z142+(P142*2.6*T142/U142)*N142*2/Z142)*AB142 -> 16898.918 | AF142: =AL142/AE142*1000 -> 710.10462 | AG142: 1 | AI142: =AJ142/1.22 -> 3278.6885 | AJ142: 4000 | AK142: =AI142*Q142 -> 9836.0656 | AL142: =AK142*1.22 -> 12000
A143: U88 | B143: Республика Башкортостан | C143: Уфа | D143: Дёмский | E143: Дёмский_мкрн. Цветы Башкирии | F143: А | G143: 46217 | H143: Комфорт | I143: ЖК Яркий Квартал Париж 3 | J143: улица Архитектора Калимуллина, 12 | K143: 54.694867 | L143: 55.859257 | M143: 2025 | N143: 26 | O143: 288 | P143: =O143*2.8 -> 806.4 | Q143: 3 | R143: 0 | S143: 1 | T143: 3 | U143: 4 | V143: Вертикальный 4*3 | W143: Digital (без звука) | X143: видеоролик | Y143: 10 | Z143: 150 | AA143: 576 | AB143: 31 | AC143: =Q143*AA143*AB143 -> 53568 | AD143: =AE143/P143 -> 20.956 | AE143: =((P143*2.6*R143/S143/2)*30/Z143+(P143*2.6*T143/U143)*N143*2/Z143)*AB143 -> 16898.918 | AF143: =AL143/AE143*1000 -> 710.10462 | AG143: 1 | AI143: =AJ143/1.22 -> 3278.6885 | AJ143: 4000 | AK143: =AI143*Q143 -> 9836.0656 | AL143: =AK143*1.22 -> 12000
A144: U89 | B144: Республика Башкортостан | C144: Уфа | D144: Дёмский | E144: Дёмский_мкрн. Цветы Башкирии | F144: А | G144: 46202 | H144: Стандарт | I144: ЖК Новая Дёма | J144: улица Генерала Кусимова, 20 | K144: 54.717392 | L144: 55.842467 | M144: 2025 | N144: 19 | O144: 808 | P144: =O144*2.8 -> 2262.4 | Q144: 8 | R144: 0 | S144: 8 | T144: 8 | U144: 16 | V144: Вертикальный 4*3 | W144: Digital (без звука) | X144: видеоролик | Y144: 10 | Z144: 150 | AA144: 576 | AB144: 31 | AC144: =Q144*AA144*AB144 -> 142848 | AD144: =AE144/P144 -> 10.209333 | AE144: =((P144*2.6*R144/S144/2)*30/Z144+(P144*2.6*T144/U144)*N144*2/Z144)*AB144 -> 23097.596 | AF144: =AL144/AE144*1000 -> 1385.4256 | AG144: 1 | AI144: =AJ144/1.22 -> 3278.6885 | AJ144: 4000 | AK144: =AI144*Q144 -> 26229.508 | AL144: =AK144*1.22 -> 32000
... A181: U120 | B181: Республика Башкортостан | C181: Уфа | D181: Кировский | E181: Зеленая Роща 2 | F181: Б | G181: 46248 | H181: Комфорт | I181: ЖК на Перовской 54 | J181: улица Софьи Перовской, 54 | K181: 54.697172 | L181: 55.992477 | M181: 2010 | N181: 18 | O181: 321 | P181: =O181*2.8 -> 898.8 | Q181: 5 | R181: 0 | S181: 5 | T181: 5 | U181: 10 | V181: Вертикальный 4*3 | W181: Digital (без звука) | X181: видеоролик | Y181: 10 | Z181: 150 | AA181: 576 | AB181: 31 | AC181: =Q181*AA181*AB181 -> 89280 | AD181: =AE181/P181 -> 9.672 | AE181: =((P181*2.6*R181/S181/2)*30/Z181+(P181*2.6*T181/U181)*N181*2/Z181)*AB181 -> 8693.1936 | AF181: =AL181/AE181*1000 -> 2300.6505 | AG181: 1 | AI181: =AJ181/1.22 -> 3278.6885 | AJ181: 4000 | AK181: =AI181*Q181 -> 16393.443 | AL181: =AK181*1.22 -> 20000
A182: U121 | B182: Республика Башкортостан | C182: Уфа | D182: Октябрьский | F182: Б | G182: 46254 | H182: Комфорт | I182: ЖК на Набережной реки Уфы 3/5 | J182: улица Набережная реки Уфы, 3/5 | K182: 54.761940 | L182: 56.052637 | M182: 2000 | N182: 10 | O182: 86 | P182: =O182*2.8 -> 240.8 | Q182: 2 | R182: 0 | S182: 2 | T182: 2 | U182: 2 | V182: Вертикальный 4*3 | W182: Digital (без звука) | X182: видеоролик | Y182: 10 | Z182: 150 | AA182: 576 | AB182: 31 | AC182: =Q182*AA182*AB182 -> 35712 | AD182: =AE182/P182 -> 10.746667 | AE182: =((P182*2.6*R182/S182/2)*30/Z182+(P182*2.6*T182/U182)*N182*2/Z182)*AB182 -> 2587.7973 | AF182: =AL182/AE182*1000 -> 3091.4322 | AG182: 1 | AI182: =AJ182/1.22 -> 3278.6885 | AJ182: 4000 | AK182: =AI182*Q182 -> 6557.377 | AL182: =AK182*1.22 -> 8000
A183: U122 | B183: Республика Башкортостан | C183: Уфа | D183: Первомайский | F183: Б | G183: 46254 | H183: Стандарт | I183: ЖК Мечтателей | J183: улица Рашита Нигмати, 12 | K183: 54.710131 | L183: 55.842665 | M183: 2025 | N183: 12 | O183: 289 | P183: =O183*2.8 -> 809.2 | Q183: 5 | R183: 0 | S183: 5 | T183: 5 | U183: 4 | V183: Вертикальный 4*3 | W183: Digital (без звука) | X183: видеоролик | Y183: 10 | Z183: 150 | AA183: 576 | AB183: 31 | AC183: =Q183*AA183*AB183 -> 89280 | AD183: =AE183/P183 -> 16.12 | AE183: =((P183*2.6*R183/S183/2)*30/Z183+(P183*2.6*T183/U183)*N183*2/Z183)*AB183 -> 13044.304 | AF183: =AL183/AE183*1000 -> 1533.2363 | AG183: 1 | AI183: =AJ183/1.22 -> 3278.6885 | AJ183: 4000 | AK183: =AI183*Q183 -> 16393.443 | AL183: =AK183*1.22 -> 20000
A184: STR1 | B184: Республика Башкортостан | C184: Стерлитамак | D184: ​Западный | E184: продажа городом | F184: А | G184: 45972 | H184: Комфорт | I184: ЖК Браво | J184: улица Интернациональная, 61 | K184: 54.811887 | L184: 56.077233 | M184: 2024 | N184: 10 | O184: 519 | P184: =O184*2.8 -> 1453.2 | Q184: 10 | R184: 5 | S184: 1 | T184: 5 | U184: 7 | V184: Горизонтальный 4*3 | W184: Digital (без звука) | X184: видеоролик | Y184: 10 | Z184: 150 | AA184: 576 | AB184: 31 | AC184: =Q184*AA184*AB184 -> 178560 | AD184: =AE184/P184 -> 47.97619 | AE184: =((P184*2.6*R184/S184/2)*30/Z184+(P184*2.6*T184/U184)*N184*2/Z184)*AB184 -> 69719 | AF184: =AL184/AE184*1000 -> 573.73169 | AG184: 1 | AI184: =AJ184/1.22 -> 3278.6885 | AJ184: 4000 | AK184: =AI184*Q184 -> 32786.885 | AL184: =AK184*1.22 -> 40000
A185: STR2 | B185: Республика Башкортостан | C185: Стерлитамак | D185: ​Западный | E185: продажа городом | F185: А | G185: 46219 | H185: Комфорт | I185: ЖК Браво 2 | J185: улица Интернациональная, 63 | K185: 54.811726 | L185: 56.077790 | M185: 2025 | N185: 17 | O185: 363 | P185: =363*2.8 -> 1016.4 | Q185: 10 | R185: 5 | S185: 5 | T185: 5 | U185: 10 | V185: Горизонтальный 4*3 | W185: Digital (без звука) | X185: видеоролик | Y185: 10 | Z185: 150 | AA185: 576 | AB185: 31 | AC185: =Q185*AA185*AB185 -> 178560 | AD185: =AE185/P185 -> 17.194667 | AE185: =((P185*2.6*R185/S185/2)*30/Z185+(P185*2.6*T185/U185)*N185*2/Z185)*AB185 -> 17476.659 | AF185: =AL185/AE185*1000 -> 2288.767 | AG185: 1 | AI185: =AJ185/1.22 -> 3278.6885 | AJ185: 4000 | AK185: =AI185*Q185 -> 32786.885 | AL185: =AK185*1.22 -> 40000
A186: STR3 | B186: Республика Башкортостан | C186: Стерлитамак | D186: Западный | E186: продажа городом | F186: А | G186: 45951 | H186: Комфорт | I186: ЖК Шиханы | J186: проспект Октября, 99 | K186: 53.629169 | L186: 55.883017 | M186: 2023 | N186: 20 | O186: 439 | P186: =O186*2.8 -> 1229.2 | Q186: 6 | R186: 3 | S186: 1 | T186: 3 | U186: 6 | V186: Горизонтальный 4*3 | W186: Digital (без звука) | X186: видеоролик | Y186: 10 | Z186: 150 | AA186: 576 | AB186: 31 | AC186: =Q186*AA186*AB186 -> 107136 | AD186: =AE186/P186 -> 34.926667 | AE186: =((P186*2.6*R186/S186/2)*30/Z186+(P186*2.6*T186/U186)*N186*2/Z186)*AB186 -> 42931.859 | AF186: =AL186/AE186*1000 -> 559.02541 | AG186: 1 | AI186: =AJ186/1.22 -> 3278.6885 | AJ186: 4000 | AK186: =AI186*Q186 -> 19672.131 | AL186: =AK186*1.22 -> 24000
A187: STR4 | B187: Республика Башкортостан | C187: Стерлитамак | D187: Западный | E187: продажа городом | F187: А | G187: 46122 | H187: Комфорт | I187: ЖК Шиханы 2 | J187: улица Раиса Багаутдинова, 2 | K187: 53.627989 | L187: 55.883080 | M187: 2024 | N187: 11 | O187: 124 | P187: =O187*2.8 -> 347.2 | Q187: 4 | R187: 2 | S187: 1 | T187: 2 | U187: 3 | V187: Горизонтальный 4*3 | W187: Digital (без звука) | X187: видеоролик | Y187: 10 | Z187: 150 | AA187: 576 | AB187: 31 | AC187: =Q187*AA187*AB187 -> 71424 | AD187: =AE187/P187 -> 24.000889 | AE187: =((P187*2.6*R187/S187/2)*30/Z187+(P187*2.6*T187/U187)*N187*2/Z187)*AB187 -> 8333.1086 | AF187: =AL187/AE187*1000 -> 1920.0518 | AG187: 1 | AI187: =AJ187/1.22 -> 3278.6885 | AJ187: 4000 | AK187: =AI187*Q187 -> 13114.754 | AL187: =AK187*1.22 -> 16000
A188: STR5 | B188: Республика Башкортостан | C188: Стерлитамак | D188: ​Западный | E188: продажа городом | F188: А | G188: 46010 | H188: Комфорт | I188: ЖК на Проспекте Октября 85 | J188: проспект Октября, 85 | K188: 53.628993 | L188: 55.899941 | M188: 2019 | N188: 18 | O188: 230 | P188: =O188*2.8 -> 644 | Q188: 4 | R188: 2 | S188: 2 | T188: 2 | U188: 4 | V188: Горизонтальный 4*3 | W188: Digital (без звука) | X188: видеоролик | Y188: 10 | Z188: 150 | AA188: 576 | AB188: 31 | AC188: =Q188*AA188*AB188 -> 71424 | AD188: =AE188/P188 -> 17.732 | AE188: =((P188*2.6*R188/S188/2)*30/Z188+(P188*2.6*T188/U188)*N188*2/Z188)*AB188 -> 11419.408 | AF188: =AL188/AE188*1000 -> 1401.1234 | AG188: 1 | AI188: =AJ188/1.22 -> 3278.6885 | AJ188: 4000 | AK188: =AI188*Q188 -> 13114.754 | AL188: =AK188*1.22 -> 16000
A189: NFT1 | B189: Республика Башкортостан | C189: Нефтекамск | D189: ​13-й м-н | E189: продажа городом | F189: Б | G189: 46230 | H189: Комфорт | I189: ЖК Лайф | J189: улица Ленина, 84Б | K189: 56.108256 | L189: 54.235974 | M189: 2024 | N189: 16 | O189: 283 | P189: =O189*2.8 -> 792.4 | Q189: 4 | R189: 0 | S189: 2 | T189: 4 | U189: 4 | V189: Вертикальный 4*3 | W189: Digital (без звука) | X189: видеоролик | Y189: 10 | Z189: 150 | AA189: 576 | AB189: 31 | AC189: =Q189*AA189*AB189 -> 71424 | AD189: =AE189/P189 -> 17.194667 | AE189: =((P189*2.6*R189/S189/2)*30/Z189+(P189*2.6*T189/U189)*N189*2/Z189)*AB189 -> 13625.054 | AF189: =AL189/AE189*1000 -> 1174.3073 | AG189: 1 | AI189: =AJ189/1.22 -> 3278.6885 | AJ189: 4000 | AK189: =AI189*Q189 -> 13114.754 | AL189: =AK189*1.22 -> 16000
A190: NFT2 | B190: Республика Башкортостан | C190: Нефтекамск | D190: 24-й м-н | E190: продажа городом | F190: Б | G190: 46237 | H190: Комфорт | I190: ЖК Городской | J190: улица Городская, 12 | K190: 56.071248 | L190: 54.225940 | M190: 2025 | N190: 10 | O190: 210 | P190: =O190*2.8 -> 588 | Q190: 2 | R190: 0 | S190: 2 | T190: 2 | U190: 2 | V190: Вертикальный 4*3 | W190: Digital (без звука) | X190: видеоролик | Y190: 10 | Z190: 150 | AA190: 576 | AB190: 31 | AC190: =Q190*AA190*AB190 -> 35712 | AD190: =AE190/P190 -> 10.746667 | AE190: =((P190*2.6*R190/S190/2)*30/Z190+(P190*2.6*T190/U190)*N190*2/Z190)*AB190 -> 6319.04 | AF190: =AL190/AE190*1000 -> 1266.0151 | AG190: 1 | AI190: =AJ190/1.22 -> 3278.6885 | AJ190: 4000 | AK190: =AI190*Q190 -> 6557.377 | AL190: =AK190*1.22 -> 8000
...

Sheet Генеральный баннер
D1: Прайс на размещение рекламного баннера
A2: GID | B2: Регион | C2: Город | D2: Район | E2: Название пакета | F2: Категория ЖК | G2: Дата застройки экранов | H2: Класс жилья | I2: Наименование ЖК | J2: Адрес | K2: Коррдинаты (широта, долгота) | M2: Год сдачи дома | N2: Этажность | O2: Количество квартир | P2: Количество жильцов | Q2: Всего экранов | R2: Число экранов в холле | S2: Всего холлов в доме | T2: Число экранов в лифте | U2: Всего лифтов в доме | V2: Тип экрана | W2: Способ показа | X2: Формат | Y2: Период/дней | Z2: Частота контакта рекламы c 1 жителем (Frequency) | AA2: Количество контактов с рекламой (OTS) | AB2: Стоимость 1000 контактов (CPT) с НДС для Федерального и крупного бизнеса | AC2: ФО/скрин с камеры | AD2: Фото | AE2: Цена за размещение на 1 экране/месяц руб. без НДС | AF2: Цена за размещение на 1 экране/месяц руб. в т.ч НДС 22% | AG2: Стоимость размещения в 1 доме/1 месяц, руб. без НДС | AH2: Стоимость размещения в 1 доме/1 месяц, руб. в т.ч.НДС 22%
A3: U1 | B3: Республика Башкортостан | C3: Уфа | D3: Ленинский | E3: Проспект | F3: А | G3: 45839 | H3: Бизнес | I3: ЖК Видинеевский | J3: улица Пархоменко, 156Б | K3: 54.743697 | L3: 55.969246 | M3: 2021 | N3: 14 | O3: 412 | P3: =O3*2.8 -> 1153.6 | Q3: 2 | R3: 1 | S3: 3 | T3: 1 | U3: 6 | V3: Горизонтальный 4*3 | W3: Digital (без звука) | X3: статичный баннер | Y3: 31 | Z3: =AA3/P3 -> 13.433333 | AA3: =((P3*2.6*R3/S3/2)/2+(P3*2.6*T3/U3)/2)*Y3 -> 15496.693 | AB3: =AH3/AA3*1000 -> 1032.4783 | AC3: 1 | AE3: =AF3/1.22 -> 6557.377 | AF3: 8000 | AG3: =AE3*Q3 -> 13114.754 | AH3: =AG3*1.22 -> 16000
A4: U1 | B4: Республика Башкортостан | C4: Уфа | D4: Ленинский | E4: Проспект | F4: А | G4: 45839 | H4: Бизнес | I4: ЖК Видинеевский | J4: улица Пархоменко, 156В | K4: 54.744659 | L4: 55.969713 | M4: 2019 | N4: 26 | O4: 232 | P4: =O4*2.8 -> 649.6 | Q4: 2 | R4: 1 | S4: 1 | T4: 1 | U4: 3 | V4: Горизонтальный 4*3 | W4: Digital (без звука) | X4: статичный баннер | Y4: 31 | Z4: =AA4/P4 -> 33.583333 | AA4: =((P4*2.6*R4/S4/2)/2+(P4*2.6*T4/U4)/2)*Y4 -> 21815.733 | AB4: =AH4/AA4*1000 -> 733.41564 | AC4: 1 | AE4: =AF4/1.22 -> 6557.377 | AF4: 8000 | AG4: =AE4*Q4 -> 13114.754 | AH4: =AG4*1.22 -> 16000
A5: U1 | B5: Республика Башкортостан | C5: Уфа | D5: Ленинский | E5: Проспект | F5: А | G5: 45839 | H5: Бизнес | I5: ЖК Видинеевский | J5: улица Пархоменко, 156Г | K5: 54.744939 | L5: 55.970603 | M5: 2023 | N5: 25 | O5: 173 | P5: =O5*2.8 -> 484.4 | Q5: 1 | R5: 0 | S5: 1 | T5: 1 | U5: 3 | V5: Горизонтальный 4*3 | W5: Digital (без звука) | X5: статичный баннер | Y5: 31 | Z5: =AA5/P5 -> 13.433333 | AA5: =((P5*2.6*R5/S5/2)/2+(P5*2.6*T5/U5)/2)*Y5 -> 6507.1067 | AB5: =AH5/AA5*1000 -> 1229.4251 | AC5: 1 | AE5: =AF5/1.22 -> 6557.377 | AF5: 8000 | AG5: =AE5*Q5 -> 6557.377 | AH5: =AG5*1.22 -> 8000
A6: U1 | B6: Республика Башкортостан | C6: Уфа | D6: Ленинский | E6: Проспект | F6: А | G6: 45839 | H6: Бизнес | I6: ЖК Видинеевский | J6: лица Пархоменко, 156Е | K6: 54.744482 | L6: 55.972408 | M6: 2025 | N6: 26 | O6: 233 | P6: =O6*2.8 -> 652.4 | Q6: 3 | R6: 0 | S6: 1 | T6: 3 | U6: 3 | V6: Горизонтальный 4*3 | W6: Digital (без звука) | X6: статичный баннер | Y6: 31 | Z6: =AA6/P6 -> 40.3 | AA6: =((P6*2.6*R6/S6/2)/2+(P6*2.6*T6/U6)/2)*Y6 -> 26291.72 | AB6: =AH6/AA6*1000 -> 912.83492 | AC6: 1 | AE6: =AF6/1.22 -> 6557.377 | AF6: 8000 | AG6: =AE6*Q6 -> 19672.131 | AH6: =AG6*1.22 -> 24000
A7: U1 | B7: Республика Башкортостан | C7: Уфа | D7: Ленинский | E7: Проспект | F7: А | G7: 45839 | H7: Бизнес | I7: ЖК Видинеевский | J7: улица Пархоменко, 156Ж | K7: 54.743999 | L7: 55.972094 | M7: 2024 | N7: 15 | O7: 289 | P7: =O7*2.8 -> 809.2 | Q7: 4 | R7: 2 | S7: 1 | T7: 2 | U7: 4 | V7: Горизонтальный 4*3 | W7: Digital (без звука) | X7: статичный баннер | Y7: 31 | Z7: =AA7/P7 -> 60.45 | AA7: =((P7*2.6*R7/S7/2)/2+(P7*2.6*T7/U7)/2)*Y7 -> 48916.14 | AB7: =AH7/AA7*1000 -> 654.18081 | AC7: 1 | AE7: =AF7/1.22 -> 6557.377 | AF7: 8000 | AG7: =AE7*Q7 -> 26229.508 | AH7: =AG7*1.22 -> 32000
A8: U2 | B8: Республика Башкортостан | C8: Уфа | D8: Кировский | E8: Зеленая Роща 2 | F8: Б | G8: 45985 | H8: Комфорт | I8: ЖК Южный | J8: улица Генерала Рыленко, 8 | K8: 54.695476 | L8: 55.989638 | M8: 2021 | N8: 28 | O8: 301 | P8: =O8*2.8 -> 842.8 | Q8: 3 | R8: 1 | S8: 1 | T8: 2 | U8: 4 | V8: Горизонтальный 4*3 | W8: Digital (без звука) | X8: статичный баннер | Y8: 31 | Z8: =AA8/P8 -> 40.3 | AA8: =((P8*2.6*R8/S8/2)/2+(P8*2.6*T8/U8)/2)*Y8 -> 33964.84 | AB8: =AH8/AA8*1000 -> 706.61307 | AC8: 1 | AE8: =AF8/1.22 -> 6557.377 | AF8: 8000 | AG8: =AE8*Q8 -> 19672.131 | AH8: =AG8*1.22 -> 24000
A9: U3 | B9: Республика Башкортостан | C9: Уфа | D9: Кировский | E9: Центр | F9: А | G9: 45950 | H9: Бизнес | I9: ЖК Выбор первых | J9: улица Айская, 61 | K9: 54.727375 | L9: 55.976172 | M9: 2024 | N9: 10 | O9: 329 | P9: =O9*2.8 -> 921.2 | Q9: 5 | R9: 0 | S9: 5 | T9: 5 | U9: 5 | V9: Горизонтальный 4*3 | W9: Digital (без звука) | X9: статичный баннер | Y9: 31 | Z9: =AA9/P9 -> 40.3 | AA9: =((P9*2.6*R9/S9/2)/2+(P9*2.6*T9/U9)/2)*Y9 -> 37124.36 | AB9: =AH9/AA9*1000 -> 1077.4597 | AC9: 1 | AE9: =AF9/1.22 -> 6557.377 | AF9: 8000 | AG9: =AE9*Q9 -> 32786.885 | AH9: =AG9*1.22 -> 40000
A10: U4 | B10: Республика Башкортостан | C10: Уфа | D10: Калининский | E10: Инорс_Сипайлово | F10: Б | G10: 45961 | H10: Стандарт | I10: ЖК Акварель | J10: улица Лётчика Кобелева, 1 | K10: 54.778409 | L10: 56.137887 | M10: 2023 | N10: 19 | O10: 102 | P10: =O10*2.8 -> 285.6 | Q10: 1 | R10: 1 | S10: 8 | T10: 0 | U10: 16 | V10: Горизонтальный 4*3 | W10: Digital (без звука) | X10: статичный баннер | Y10: 31 | Z10: =AA10/P10 -> 2.51875 | AA10: =((P10*2.6*R10/S10/2)/2+(P10*2.6*T10/U10)/2)*Y10 -> 719.355 | AB10: =AH10/AA10*1000 -> 11121.074 | AC10: 1 | AE10: =AF10/1.22 -> 6557.377 | AF10: 8000 | AG10: =AE10*Q10 -> 6557.377 | AH10: =AG10*1.22 -> 8000
A11: U4 | B11: Республика Башкортостан | C11: Уфа | D11: Калининский | E11: Инорс_Сипайлово | F11: Б | G11: 45961 | H11: Стандарт | I11: ЖК Акварель | J11: улица Лётчика Кобелева, 3/3 | K11: 54.778180 | L11: 56.134411 | M11: 2018 | N11: 27 | O11: 338 | P11: =O11*2.8 -> 946.4 | Q11: 1 | R11: 1 | S11: 1 | T11: 0 | U11: 3 | V11: Горизонтальный 4*3 | W11: Digital (без звука) | X11: статичный баннер | Y11: 31 | Z11: =AA11/P11 -> 20.15 | AA11: =((P11*2.6*R11/S11/2)/2+(P11*2.6*T11/U11)/2)*Y11 -> 19069.96 | AB11: =AH11/AA11*1000 -> 419.50796 | AC11: 1 | AE11: =AF11/1.22 -> 6557.377 | AF11: 8000 | AG11: =AE11*Q11 -> 6557.377 | AH11: =AG11*1.22 -> 8000
